/usr/lib/python2.7/dist-packages/h5py/__init__.py:36: FutureWarning: Conversion of the second argument of issubdtype from `float` to `np.floating` is deprecated. In future, it will be treated as `np.float64 == np.dtype(float).type`.
  from ._conv import register_converters as _register_converters
2020-02-12 10:25:55.080662: I tensorflow/core/platform/cpu_feature_guard.cc:141] Your CPU supports instructions that this TensorFlow binary was not compiled to use: AVX2 AVX512F FMA
2020-02-12 10:25:55.090035: I tensorflow/core/distributed_runtime/rpc/grpc_channel.cc:222] Initialize GrpcChannelCache for job ps -> {0 -> node1:2000}
2020-02-12 10:25:55.090057: I tensorflow/core/distributed_runtime/rpc/grpc_channel.cc:222] Initialize GrpcChannelCache for job worker -> {0 -> localhost:2001}
2020-02-12 10:25:55.096017: I tensorflow/core/distributed_runtime/rpc/grpc_server_lib.cc:381] Started server with target: grpc://localhost:2001
WARNING: Logging before InitGoogleLogging() is written to STDERR
I0212 10:25:55.096737 55599 remote_graph.cc:91] Initialize RemoteGraph, connect to server monitor: [node1:2181, /euler]
WARNING: Logging before InitGoogleLogging() is written to STDERR
I0212 10:25:56.805899 56047 graph_builder.cc:81] Load Done: hdfs://node1:9000/data/ppi/ppi_data_0.dat
I0212 10:25:56.807088 56049 graph_builder.cc:81] Load Done: hdfs://node1:9000/data/ppi/ppi_data_2.dat
I0212 10:25:56.814072 56050 graph_builder.cc:81] Load Done: hdfs://node1:9000/data/ppi/ppi_data_3.dat
I0212 10:25:56.816054 56048 graph_builder.cc:81] Load Done: hdfs://node1:9000/data/ppi/ppi_data_1.dat
I0212 10:25:56.816718 55939 graph_builder.cc:127] Each Thread Load Finish! Node Count:56944 Edge Count:1612348
I0212 10:25:56.816735 55939 graph_builder.cc:135] Graph Loading Finish!
I0212 10:25:57.175500 55939 graph_builder.cc:147] Graph Load Finish! Node Count:56944 Edge Count:1612348
I0212 10:25:57.185263 55939 graph_builder.cc:152] Done: build node sampler
I0212 10:25:57.185276 55939 graph_builder.cc:162] Graph build finish
I0212 10:25:57.185911 55939 graph_service.cc:179] service init finish
I0212 10:25:57.186759 55939 graph_service.cc:131] bound port: 172.31.45.116:40789
W0212 10:25:57.191828 55939 graph.h:198] global sampler is not ok
I0212 10:25:57.193372 55939 graph_service.cc:146] service start
I0212 10:25:57.194238 55948 zk_server_monitor.cc:238] Online node: 0#172.31.45.116:40789.
I0212 10:25:57.194571 55599 remote_graph.cc:106] Retrieve meta info success, shard number: 1
I0212 10:25:57.194586 55599 remote_graph.cc:119] Retrieve meta info success, partition number: 4
I0212 10:25:57.194599 55599 remote_graph.cc:190] Retrieve Shard Meta Info successfully, shard: 0, Key: node_sum_weight, Meta Info: 44906.000000,6514.000000,5524.000000
I0212 10:25:57.194604 55599 remote_graph.cc:190] Retrieve Shard Meta Info successfully, shard: 0, Key: edge_sum_weight, Meta Info: 
INFO:tensorflow:Create CheckpointSaverHook.
INFO:tensorflow:Graph was finalized.
2020-02-12 10:25:57.510636: I tensorflow/core/distributed_runtime/master_session.cc:1161] Start master session b47864f50459af85 with config: gpu_options { allow_growth: true }
INFO:tensorflow:Running local_init_op.
INFO:tensorflow:Done running local_init_op.
INFO:tensorflow:Saving checkpoints for 0 into ckpt/model.ckpt.
Traceback (most recent call last):
  File "/usr/lib/python2.7/runpy.py", line 174, in _run_module_as_main
    "__main__", fname, loader, pkg_name)
  File "/usr/lib/python2.7/runpy.py", line 72, in _run_code
    exec code in run_globals
  File "/usr/local/lib/python2.7/dist-packages/euler_gl-0.1.2-py2.7.egg/tf_euler/__main__.py", line 28, in <module>
    tf.app.run(run_loop.main)
  File "/usr/local/lib/python2.7/dist-packages/tensorflow/python/platform/app.py", line 125, in run
    _sys.exit(main(argv))
  File "/usr/local/lib/python2.7/dist-packages/euler_gl-0.1.2-py2.7.egg/tf_euler/python/run_loop.py", line 403, in main
    run_distributed(flags_obj, run_network_embedding)
  File "/usr/local/lib/python2.7/dist-packages/euler_gl-0.1.2-py2.7.egg/tf_euler/python/run_loop.py", line 395, in run_distributed
    run(flags_obj, server.target, flags_obj.task_index == 0)
  File "/usr/local/lib/python2.7/dist-packages/euler_gl-0.1.2-py2.7.egg/tf_euler/python/run_loop.py", line 357, in run_network_embedding
    run_train(model, flags_obj, master, is_chief)
  File "/usr/local/lib/python2.7/dist-packages/euler_gl-0.1.2-py2.7.egg/tf_euler/python/run_loop.py", line 138, in run_train
    config=config) as sess:
  File "/usr/local/lib/python2.7/dist-packages/tensorflow/python/training/monitored_session.py", line 504, in MonitoredTrainingSession
    stop_grace_period_secs=stop_grace_period_secs)
  File "/usr/local/lib/python2.7/dist-packages/tensorflow/python/training/monitored_session.py", line 921, in __init__
    stop_grace_period_secs=stop_grace_period_secs)
  File "/usr/local/lib/python2.7/dist-packages/tensorflow/python/training/monitored_session.py", line 643, in __init__
    self._sess = _RecoverableSession(self._coordinated_creator)
  File "/usr/local/lib/python2.7/dist-packages/tensorflow/python/training/monitored_session.py", line 1107, in __init__
    _WrappedSession.__init__(self, self._create_session())
  File "/usr/local/lib/python2.7/dist-packages/tensorflow/python/training/monitored_session.py", line 1112, in _create_session
    return self._sess_creator.create_session()
  File "/usr/local/lib/python2.7/dist-packages/tensorflow/python/training/monitored_session.py", line 807, in create_session
    hook.after_create_session(self.tf_sess, self.coord)
  File "/usr/local/lib/python2.7/dist-packages/tensorflow/python/training/basic_session_run_hooks.py", line 568, in after_create_session
    self._save(session, global_step)
  File "/usr/local/lib/python2.7/dist-packages/tensorflow/python/training/basic_session_run_hooks.py", line 599, in _save
    self._get_saver().save(session, self._save_path, global_step=step)
  File "/usr/local/lib/python2.7/dist-packages/tensorflow/python/training/saver.py", line 1458, in save
    raise exc
tensorflow.python.framework.errors_impl.NotFoundError: ckpt/model.ckpt-0_temp_ea8b250cbdd5439b96e9a379ae979a81; No such file or directory
	 [[node save/SaveV2 (defined at /usr/local/lib/python2.7/dist-packages/euler_gl-0.1.2-py2.7.egg/tf_euler/python/run_loop.py:138)  = SaveV2[dtypes=[DT_FLOAT, DT_FLOAT, DT_INT64, DT_FLOAT, DT_FLOAT, DT_FLOAT, DT_FLOAT, DT_FLOAT, DT_FLOAT], _device="/job:ps/replica:0/task:0/device:CPU:0"](save/ShardedFilename, save/SaveV2/tensor_names, save/SaveV2/shape_and_slices, beta1_power, beta2_power, global_step, node2vec_1/shallowencoder_1/embedding_1/embeddings, node2vec_1/shallowencoder_1/embedding_1/embeddings/Adam, node2vec_1/shallowencoder_1/embedding_1/embeddings/Adam_1, node2vec_1/shallowencoder_2/embedding_2/embeddings, node2vec_1/shallowencoder_2/embedding_2/embeddings/Adam, node2vec_1/shallowencoder_2/embedding_2/embeddings/Adam_1)]]
	 [[{{node save/Identity_S63}} = _HostRecv[client_terminated=false, recv_device="/job:worker/replica:0/task:0/device:CPU:0", send_device="/job:ps/replica:0/task:0/device:CPU:0", send_device_incarnation=-4991114998378154634, tensor_name="edge_44_save/Identity", tensor_type=DT_STRING, _device="/job:worker/replica:0/task:0/device:CPU:0"]()]]

Caused by op u'save/SaveV2', defined at:
  File "/usr/lib/python2.7/runpy.py", line 174, in _run_module_as_main
    "__main__", fname, loader, pkg_name)
  File "/usr/lib/python2.7/runpy.py", line 72, in _run_code
    exec code in run_globals
  File "/usr/local/lib/python2.7/dist-packages/euler_gl-0.1.2-py2.7.egg/tf_euler/__main__.py", line 28, in <module>
    tf.app.run(run_loop.main)
  File "/usr/local/lib/python2.7/dist-packages/tensorflow/python/platform/app.py", line 125, in run
    _sys.exit(main(argv))
  File "/usr/local/lib/python2.7/dist-packages/euler_gl-0.1.2-py2.7.egg/tf_euler/python/run_loop.py", line 403, in main
    run_distributed(flags_obj, run_network_embedding)
  File "/usr/local/lib/python2.7/dist-packages/euler_gl-0.1.2-py2.7.egg/tf_euler/python/run_loop.py", line 395, in run_distributed
    run(flags_obj, server.target, flags_obj.task_index == 0)
  File "/usr/local/lib/python2.7/dist-packages/euler_gl-0.1.2-py2.7.egg/tf_euler/python/run_loop.py", line 357, in run_network_embedding
    run_train(model, flags_obj, master, is_chief)
  File "/usr/local/lib/python2.7/dist-packages/euler_gl-0.1.2-py2.7.egg/tf_euler/python/run_loop.py", line 138, in run_train
    config=config) as sess:
  File "/usr/local/lib/python2.7/dist-packages/tensorflow/python/training/monitored_session.py", line 504, in MonitoredTrainingSession
    stop_grace_period_secs=stop_grace_period_secs)
  File "/usr/local/lib/python2.7/dist-packages/tensorflow/python/training/monitored_session.py", line 921, in __init__
    stop_grace_period_secs=stop_grace_period_secs)
  File "/usr/local/lib/python2.7/dist-packages/tensorflow/python/training/monitored_session.py", line 643, in __init__
    self._sess = _RecoverableSession(self._coordinated_creator)
  File "/usr/local/lib/python2.7/dist-packages/tensorflow/python/training/monitored_session.py", line 1107, in __init__
    _WrappedSession.__init__(self, self._create_session())
  File "/usr/local/lib/python2.7/dist-packages/tensorflow/python/training/monitored_session.py", line 1112, in _create_session
    return self._sess_creator.create_session()
  File "/usr/local/lib/python2.7/dist-packages/tensorflow/python/training/monitored_session.py", line 800, in create_session
    self.tf_sess = self._session_creator.create_session()
  File "/usr/local/lib/python2.7/dist-packages/tensorflow/python/training/monitored_session.py", line 557, in create_session
    self._scaffold.finalize()
  File "/usr/local/lib/python2.7/dist-packages/tensorflow/python/training/monitored_session.py", line 213, in finalize
    self._saver = training_saver._get_saver_or_default()  # pylint: disable=protected-access
  File "/usr/local/lib/python2.7/dist-packages/tensorflow/python/training/saver.py", line 886, in _get_saver_or_default
    saver = Saver(sharded=True, allow_empty=True)
  File "/usr/local/lib/python2.7/dist-packages/tensorflow/python/training/saver.py", line 1102, in __init__
    self.build()
  File "/usr/local/lib/python2.7/dist-packages/tensorflow/python/training/saver.py", line 1114, in build
    self._build(self._filename, build_save=True, build_restore=True)
  File "/usr/local/lib/python2.7/dist-packages/tensorflow/python/training/saver.py", line 1151, in _build
    build_save=build_save, build_restore=build_restore)
  File "/usr/local/lib/python2.7/dist-packages/tensorflow/python/training/saver.py", line 786, in _build_internal
    save_tensor = self._AddShardedSaveOps(filename_tensor, per_device)
  File "/usr/local/lib/python2.7/dist-packages/tensorflow/python/training/saver.py", line 369, in _AddShardedSaveOps
    return self._AddShardedSaveOpsForV2(filename_tensor, per_device)
  File "/usr/local/lib/python2.7/dist-packages/tensorflow/python/training/saver.py", line 343, in _AddShardedSaveOpsForV2
    sharded_saves.append(self._AddSaveOps(sharded_filename, saveables))
  File "/usr/local/lib/python2.7/dist-packages/tensorflow/python/training/saver.py", line 284, in _AddSaveOps
    save = self.save_op(filename_tensor, saveables)
  File "/usr/local/lib/python2.7/dist-packages/tensorflow/python/training/saver.py", line 202, in save_op
    tensors)
  File "/usr/local/lib/python2.7/dist-packages/tensorflow/python/ops/gen_io_ops.py", line 1690, in save_v2
    shape_and_slices=shape_and_slices, tensors=tensors, name=name)
  File "/usr/local/lib/python2.7/dist-packages/tensorflow/python/framework/op_def_library.py", line 787, in _apply_op_helper
    op_def=op_def)
  File "/usr/local/lib/python2.7/dist-packages/tensorflow/python/util/deprecation.py", line 488, in new_func
    return func(*args, **kwargs)
  File "/usr/local/lib/python2.7/dist-packages/tensorflow/python/framework/ops.py", line 3274, in create_op
    op_def=op_def)
  File "/usr/local/lib/python2.7/dist-packages/tensorflow/python/framework/ops.py", line 1770, in __init__
    self._traceback = tf_stack.extract_stack()

NotFoundError (see above for traceback): ckpt/model.ckpt-0_temp_ea8b250cbdd5439b96e9a379ae979a81; No such file or directory
	 [[node save/SaveV2 (defined at /usr/local/lib/python2.7/dist-packages/euler_gl-0.1.2-py2.7.egg/tf_euler/python/run_loop.py:138)  = SaveV2[dtypes=[DT_FLOAT, DT_FLOAT, DT_INT64, DT_FLOAT, DT_FLOAT, DT_FLOAT, DT_FLOAT, DT_FLOAT, DT_FLOAT], _device="/job:ps/replica:0/task:0/device:CPU:0"](save/ShardedFilename, save/SaveV2/tensor_names, save/SaveV2/shape_and_slices, beta1_power, beta2_power, global_step, node2vec_1/shallowencoder_1/embedding_1/embeddings, node2vec_1/shallowencoder_1/embedding_1/embeddings/Adam, node2vec_1/shallowencoder_1/embedding_1/embeddings/Adam_1, node2vec_1/shallowencoder_2/embedding_2/embeddings, node2vec_1/shallowencoder_2/embedding_2/embeddings/Adam, node2vec_1/shallowencoder_2/embedding_2/embeddings/Adam_1)]]
	 [[{{node save/Identity_S63}} = _HostRecv[client_terminated=false, recv_device="/job:worker/replica:0/task:0/device:CPU:0", send_device="/job:ps/replica:0/task:0/device:CPU:0", send_device_incarnation=-4991114998378154634, tensor_name="edge_44_save/Identity", tensor_type=DT_STRING, _device="/job:worker/replica:0/task:0/device:CPU:0"]()]]

